Workbook

Sheet Lists
A1: Sector | B1: GH. | C1: Pestside Name | D1: Active Ingridiant | E1: PHI | F1: MRL EU | G1: MRL GB | H1: Target Pest | I1: Status | J1: Uint | Q1: A | R1: 80 | S1: 1
A2: 1 | B2: 1 | C2: Egysect 5%EC | D2: Lambda-Cyhalothrin | E2: 15 | I2: Off-Label | Q2: B | R2: 80 | S2: 2
A3: 1 | B3: 2 | C3: Oikos | D3: Azadirachtin | E3: 0 | I3: Off-Label | Q3: A&B | R3: 160 | S3: 3
A4: 1 | B4: 3 | C4: Delta Star 10% EC | D4: Deltamethrin | E4: 10 | I4: Off-Label | J4: L | S4: 4
A5: 1 | B5: 4 | I5: Off-Label | S5: 5
A6: 1 | B6: 5 | C6: Prev-AM | D6: Vegetable Oil | E6: 0 | I6: Off-Label | S6: 6
A7: 1 | B7: 6 | C7: Biossiana 2.5% | D7: Beauveria bassiana | E7: 0 | I7: Off-Label | S7: 7
A8: 1 | B8: 7 | C8: Safe Oil | D8: Azadirachtin | E8: 0 | I8: Off-Label | S8: 8
A9: 1 | B9: 8 | C9: Protecto 9.4 % WP | D9: Bacillus thuringiensis kurstaki | E9: 0 | I9: Off-Label | S9: 9
A10: 1 | B10: 9 | C10: Serenade 1.34% SC | D10: Bacillus Subtilis | E10: 0 | I10: Off-Label | S10: 10
A11: 1 | B11: 10 | C11: G-Oil | D11: Vegetable Oil | E11: 0 | I11: Off-Label | S11: 11
A12: 2 | B12: 11 | C12: Provy 10%EC | D12: Pyriproxyfen | I12: Off-Label | S12: 12
A13: 2 | B13: 12 | C13: Hydrogen peroxide | D13: Hydrogen peroxide (H2O2) | E13: 0 | I13: Off-Label | S13: 13
A14: 2 | B14: 13 | C14: Hydrogen peroxide | D14: Hydrogen peroxide (H2O2) | E14: 0 | I14: Off-Label | S14: 14
A15: 2 | B15: 14 | C15: Ran Way 25% SC | D15: Buprofezin | I15: Off-Label | S15: 15
A16: 2 | B16: 16 | C16: Grendo 10% EC | D16: Pyriproxyfen [10%] | E16: 10 | F16: 0.01 | G16: 0.05 | H16: Red Spider Mites | I16: On-Label | S16: 16
A17: 2 | B17: 17 | C17: Baroque10% SC | D17: Etoxazole [10%] | E17: 10 | F17: 0.01 | G17: 0.01 | H17: RSM | I17: On-Label | S17: 17
A18: 2 | B18: 18 | C18: Equo 10% EC | D18: Novaluron [10%] | E18: 7 | F18: 0.01 | G18: 7 | H18: Cotton Leaf Worms and Thrips | I18: On-Label | S18: 18
A19: 2 | B19: 19 | C19: Speedo 5.7% WG | D19: Emamectin Benzoate [5.7%] | E19: 7 | F19: 0.002 | G19: 0.01 | H19: Cotton Leaf Worms and Thrips | I19: On-Label | S19: 19
A20: 2 | B20: 20 | C20: Castello 10% EC | D20: Lufenuron [10%] | E20: 4 | F20: 0.01 | G20: 0.01 | H20: Cotton Leaf Worms and Thrips | I20: On-Label | S20: 20
A21: 3 | B21: 21 | C21: Penny 9% SC | D21: Emamectin Benzoate [1.5%]&Indoxacarb [7.5%] | E21: 7 | F21: 0.0020;0.0100 | G21: 0.0100;0.8000 | H21: caterpillars | I21: On-Label | S21: 21
A22: 3 | B22: 22 | C22: Prituo 50% WG | D22: Flonicamid (p) [50%] | E22: 7 | F22: 0.8 | G22: 1.5 | H22: Aphids | I22: On-Label | S22: 22
A23: 3 | B23: 23 | C23: Chess 50% WG | D23: Pymetrozine [50%] | E23: 21 | F23: 0.02 | G23: 0.02 | H23: Leaf Hoppers | I23: On-Label | S23: 23
A24: 3 | B24: 24 | C24: Chinook 35% SC | D24: Imidacloprid [35%] | E24: 5 | F24: 5 | G24: 5 | H24: Thrips and Aphids | I24: On-Label | S24: 24
A25: 3 | B25: 25 | C25: Applaud 25%SC | D25: Buprofezin [25%] | E25: 7 | F25: 0.01 | G25: 0.01 | H25: White Fly | I25: On-Label | S25: 25
A26: 3 | B26: 26 | I26: On-Label | S26: 26
A27: 3 | B27: 27 | C27: Sivanto Prime 20% SL | D27: Flupyradifurone [20%] | E27: 3 | F27: 4 | G27: 0.01 | H27: Aphids, blueberry maggots | I27: On-Label | S27: 27
A28: 3 | B28: 28 | C28: Karate 2.5% EC | D28: Lambda-Cyhalothrin [2.5%] | E28: 5 | F28: 0.2 | G28: 0.2 | H28: Cotton Leaf Worms and Thrips | I28: On-Label | S28: 28
A29: 3 | B29: 29 | C29: Blue Jet 85% WG | D29: Copper Oxychloride [85%] | E29: 5 | F29: 5 | G29: 5 | H29: Powdery Mildew and Fruit rots | I29: On-Label | S29: 29
A30: 3 | B30: 30 | C30: Ridomil Gold Plus 71.5% WP | D30: Metalaxyl-M [2.5%]&Copper oxychloride [69%] | E30: 30 | F30: 0.0100;5.0000 | G30: 0.0100;5.0000 | H30: after Transplant | I30: On-Label | S30: 30
A31: 5 | B31: 32 | C31: Kocide (2000) 53.8 % DF | D31: Copper hydroxide [53.8%] | E31: 2 | F31: 5 | G31: 5 | H31: Powdery Mildew | I31: On-Label | S31: 31
A32: 5 | B32: 33 | C32: Mystic Pro 50% EC | D32: Prochloraz (p) [30%]&Tebuconazole [20%] | E32: 10 | F32: 0.0300;1.5000 | G32: 0.0300;1.5000 | H32: Powdery Mildew | I32: On-Label | S32: 32
A33: 5 | B33: 34 | C33: Topas (100) 10% EC | D33: Penconazole [10%] | E33: 3 | F33: 0.01 | G33: 0.01 | H33: Powdery Mildew | I33: On-Label | S33: 33
A34: 5 | B34: 37 | C34: Fabric 30% SC | D34: Tebuconazole [15%]&Kresoxim-Methyl [15%] | E34: 5 | F34: 1.5000;0.9000 | G34: 1.5000;0.9000 | H34: Leaf spots | I34: On-Label | S34: 34
A35: 5 | B35: 38 | C35: Luna Experience 40% SC | D35: Fluopyram [20%]&Tebuconazole [20%] | E35: 3 | F35: 7.0000;1.5000 | G35: 7.0000;1.5000 | H35: Powdery Mildew | I35: On-Label | S35: 35
A36: 5 | B36: 39 | C36: Movento 10% SC | D36: Spirotetramat (p) [10%] | E36: 10 | F36: 1.5 | G36: 0.7 | H36: Thrips | I36: On-Label | S36: 36
A37: 5 | B37: 42 | C37: Milbecknok 1% EC | D37: Milbemectin A3 [1%] | E37: 7 | F37: 0.02 | G37: 0.02 | H37: RSM | I37: On-Label | S37: 37
A38: 5 | B38: 43 | C38: Flint 50% WG | D38: Trifloxystrobin [50%] | E38: 5 | F38: 3 | G38: 3 | H38: Powdery Mildew | I38: On-Label | S38: 38
A39: 5 | B39: 44 | C39: Biocontrol T34 12% WP | D39: Trichoderma asperellum (strain T34) [12%] | E39: 0 | F39: 0.01 | G39: NA | H39: Fruit rots | I39: On-Label | S39: 39
A40: 4 | B40: 46 | C40: Bio Zeid 2.5% WP | D40: Trichoderma Album [2.5%] | E40: 0 | F40: 0.01 | G40: 0.01 | H40: Powdery Mildew | I40: On-Label | S40: 40
...

Sheet IPM2026
A1: Date | B1: Gh. | C1: Sector | D1: Vulve | E1: First Line | F1: End line | G1: No. Of Lines | H1: Completion% | I1: Pesticide Name | J1: Active ingrediant | K1: Method | L1: Dose/100L(cc Or g) | M1: Water Vol.(L) | N1: Total Qty (kg OrL) | O1: Unit | P1: PHI | Q1: Allawed Harvest date | R1: Status | S1: PPL Sheet
A2: 46143 | B2: 1 | C2: =_xlfn.XLOOKUP(B2,Lists!B:B,Lists!A:A,"") -> 1 | D2: A&B | E2: 1 | F2: 160 | G2: =IF(OR(E2="",F2=""),"",F2-E2+1) -> 160 | H2: =IF(D2="","",IF(OR(D2="A",D2="B"),G2/80,IF(D2="A&B",G2/160,""))) -> 1 | I2: Trolls 25% EW | J2: =IF(I2="","",_xlfn.XLOOKUP(I2,Lists!$C:$C,Lists!$D:$D)) -> Tebuconazole 25% | K2: Spray | L2: 100 | M2: 900 | N2: =IF(OR(M2="",L2=""),"",(M2*L2)/100000) -> 0.9 | O2: =IF(I2="","",_xlfn.XLOOKUP(I2,Lists!$C:$C,Lists!$J:$J)) -> L | P2: =IF(I2="","",_xlfn.XLOOKUP(I2,Lists!$C:$C,Lists!$E:$E)) -> 45 | Q2: =IF(OR(A2="",P2=""),"",A2+P2+1) -> 46189 | R2: =IF(Q2="","",IF(Q2<=TODAY(),"Allow","Not Allow")) -> Allow | S2: =IF(I2="","",_xlfn.XLOOKUP(I2,Lists!$C:$C,Lists!$I:$I)) -> On-Label
A3: 46145 | B3: 2 | C3: =_xlfn.XLOOKUP(B3,Lists!B:B,Lists!A:A,"") -> 1 | D3: A&B | E3: 1 | F3: 160 | G3: =IF(OR(E3="",F3=""),"",F3-E3+1) -> 160 | H3: =IF(D3="","",IF(OR(D3="A",D3="B"),G3/80,IF(D3="A&B",G3/160,""))) -> 1 | I3: Trolls 25% EW | J3: =IF(I3="","",_xlfn.XLOOKUP(I3,Lists!$C:$C,Lists!$D:$D)) -> Tebuconazole 25% | K3: Spray | L3: 100 | M3: 900 | N3: =IF(OR(M3="",L3=""),"",(M3*L3)/100000) -> 0.9 | O3: =IF(I3="","",_xlfn.XLOOKUP(I3,Lists!$C:$C,Lists!$J:$J)) -> L | P3: =IF(I3="","",_xlfn.XLOOKUP(I3,Lists!$C:$C,Lists!$E:$E)) -> 45 | Q3: =IF(OR(A3="",P3=""),"",A3+P3+1) -> 46191 | R3: =IF(Q3="","",IF(Q3<=TODAY(),"Allow","Not Allow")) -> Not Allow | S3: =IF(I3="","",_xlfn.XLOOKUP(I3,Lists!$C:$C,Lists!$I:$I)) -> On-Label
A4: 46145 | B4: 11 | C4: =_xlfn.XLOOKUP(B4,Lists!B:B,Lists!A:A,"") -> 2 | D4: A&B | E4: 1 | F4: 160 | G4: =IF(OR(E4="",F4=""),"",F4-E4+1) -> 160 | H4: =IF(D4="","",IF(OR(D4="A",D4="B"),G4/80,IF(D4="A&B",G4/160,""))) -> 1 | I4: Trolls 25% EW | J4: =IF(I4="","",_xlfn.XLOOKUP(I4,Lists!$C:$C,Lists!$D:$D)) -> Tebuconazole 25% | K4: Spray | L4: 100 | M4: 900 | N4: =IF(OR(M4="",L4=""),"",(M4*L4)/100000) -> 0.9 | O4: =IF(I4="","",_xlfn.XLOOKUP(I4,Lists!$C:$C,Lists!$J:$J)) -> L | P4: =IF(I4="","",_xlfn.XLOOKUP(I4,Lists!$C:$C,Lists!$E:$E)) -> 45 | Q4: =IF(OR(A4="",P4=""),"",A4+P4+1) -> 46191 | R4: =IF(Q4="","",IF(Q4<=TODAY(),"Allow","Not Allow")) -> Not Allow | S4: =IF(I4="","",_xlfn.XLOOKUP(I4,Lists!$C:$C,Lists!$I:$I)) -> On-Label
A5: 46146 | B5: 3 | C5: =_xlfn.XLOOKUP(B5,Lists!B:B,Lists!A:A,"") -> 1 | D5: A&B | E5: 1 | F5: 160 | G5: =IF(OR(E5="",F5=""),"",F5-E5+1) -> 160 | H5: =IF(D5="","",IF(OR(D5="A",D5="B"),G5/80,IF(D5="A&B",G5/160,""))) -> 1 | I5: Trolls 25% EW | J5: =IF(I5="","",_xlfn.XLOOKUP(I5,Lists!$C:$C,Lists!$D:$D)) -> Tebuconazole 25% | K5: Spray | L5: 100 | M5: 900 | N5: =IF(OR(M5="",L5=""),"",(M5*L5)/100000) -> 0.9 | O5: =IF(I5="","",_xlfn.XLOOKUP(I5,Lists!$C:$C,Lists!$J:$J)) -> L | P5: =IF(I5="","",_xlfn.XLOOKUP(I5,Lists!$C:$C,Lists!$E:$E)) -> 45 | Q5: =IF(OR(A5="",P5=""),"",A5+P5+1) -> 46192 | R5: =IF(Q5="","",IF(Q5<=TODAY(),"Allow","Not Allow")) -> Not Allow | S5: =IF(I5="","",_xlfn.XLOOKUP(I5,Lists!$C:$C,Lists!$I:$I)) -> On-Label
A6: 46147 | B6: 4 | C6: =_xlfn.XLOOKUP(B6,Lists!B:B,Lists!A:A,"") -> 1 | D6: A&B | E6: 1 | F6: 160 | G6: =IF(OR(E6="",F6=""),"",F6-E6+1) -> 160 | H6: =IF(D6="","",IF(OR(D6="A",D6="B"),G6/80,IF(D6="A&B",G6/160,""))) -> 1 | I6: Trolls 25% EW | J6: =IF(I6="","",_xlfn.XLOOKUP(I6,Lists!$C:$C,Lists!$D:$D)) -> Tebuconazole 25% | K6: Spray | L6: 100 | M6: 900 | N6: =IF(OR(M6="",L6=""),"",(M6*L6)/100000) -> 0.9 | O6: =IF(I6="","",_xlfn.XLOOKUP(I6,Lists!$C:$C,Lists!$J:$J)) -> L | P6: =IF(I6="","",_xlfn.XLOOKUP(I6,Lists!$C:$C,Lists!$E:$E)) -> 45 | Q6: =IF(OR(A6="",P6=""),"",A6+P6+1) -> 46193 | R6: =IF(Q6="","",IF(Q6<=TODAY(),"Allow","Not Allow")) -> Not Allow | S6: =IF(I6="","",_xlfn.XLOOKUP(I6,Lists!$C:$C,Lists!$I:$I)) -> On-Label
A7: 46147 | B7: 12 | C7: =_xlfn.XLOOKUP(B7,Lists!B:B,Lists!A:A,"") -> 2 | D7: A&B | E7: 1 | F7: 160 | G7: =IF(OR(E7="",F7=""),"",F7-E7+1) -> 160 | H7: =IF(D7="","",IF(OR(D7="A",D7="B"),G7/80,IF(D7="A&B",G7/160,""))) -> 1 | I7: Trolls 25% EW | J7: =IF(I7="","",_xlfn.XLOOKUP(I7,Lists!$C:$C,Lists!$D:$D)) -> Tebuconazole 25% | K7: Spray | L7: 100 | M7: 900 | N7: =IF(OR(M7="",L7=""),"",(M7*L7)/100000) -> 0.9 | O7: =IF(I7="","",_xlfn.XLOOKUP(I7,Lists!$C:$C,Lists!$J:$J)) -> L | P7: =IF(I7="","",_xlfn.XLOOKUP(I7,Lists!$C:$C,Lists!$E:$E)) -> 45 | Q7: =IF(OR(A7="",P7=""),"",A7+P7+1) -> 46193 | R7: =IF(Q7="","",IF(Q7<=TODAY(),"Allow","Not Allow")) -> Not Allow | S7: =IF(I7="","",_xlfn.XLOOKUP(I7,Lists!$C:$C,Lists!$I:$I)) -> On-Label
A8: 46149 | B8: 5 | C8: =_xlfn.XLOOKUP(B8,Lists!B:B,Lists!A:A,"") -> 1 | D8: A&B | E8: 1 | F8: 160 | G8: =IF(OR(E8="",F8=""),"",F8-E8+1) -> 160 | H8: =IF(D8="","",IF(OR(D8="A",D8="B"),G8/80,IF(D8="A&B",G8/160,""))) -> 1 | I8: Trolls 25% EW | J8: =IF(I8="","",_xlfn.XLOOKUP(I8,Lists!$C:$C,Lists!$D:$D)) -> Tebuconazole 25% | K8: Spray | L8: 100 | M8: 900 | N8: =IF(OR(M8="",L8=""),"",(M8*L8)/100000) -> 0.9 | O8: =IF(I8="","",_xlfn.XLOOKUP(I8,Lists!$C:$C,Lists!$J:$J)) -> L | P8: =IF(I8="","",_xlfn.XLOOKUP(I8,Lists!$C:$C,Lists!$E:$E)) -> 45 | Q8: =IF(OR(A8="",P8=""),"",A8+P8+1) -> 46195 | R8: =IF(Q8="","",IF(Q8<=TODAY(),"Allow","Not Allow")) -> Not Allow | S8: =IF(I8="","",_xlfn.XLOOKUP(I8,Lists!$C:$C,Lists!$I:$I)) -> On-Label
A9: 46149 | B9: 13 | C9: =_xlfn.XLOOKUP(B9,Lists!B:B,Lists!A:A,"") -> 2 | D9: A&B | E9: 1 | F9: 160 | G9: =IF(OR(E9="",F9=""),"",F9-E9+1) -> 160 | H9: =IF(D9="","",IF(OR(D9="A",D9="B"),G9/80,IF(D9="A&B",G9/160,""))) -> 1 | I9: Trolls 25% EW | J9: =IF(I9="","",_xlfn.XLOOKUP(I9,Lists!$C:$C,Lists!$D:$D)) -> Tebuconazole 25% | K9: Spray | L9: 100 | M9: 900 | N9: =IF(OR(M9="",L9=""),"",(M9*L9)/100000) -> 0.9 | O9: =IF(I9="","",_xlfn.XLOOKUP(I9,Lists!$C:$C,Lists!$J:$J)) -> L | P9: =IF(I9="","",_xlfn.XLOOKUP(I9,Lists!$C:$C,Lists!$E:$E)) -> 45 | Q9: =IF(OR(A9="",P9=""),"",A9+P9+1) -> 46195 | R9: =IF(Q9="","",IF(Q9<=TODAY(),"Allow","Not Allow")) -> Not Allow | S9: =IF(I9="","",_xlfn.XLOOKUP(I9,Lists!$C:$C,Lists!$I:$I)) -> On-Label
A10: 46149 | B10: 32 | C10: =_xlfn.XLOOKUP(B10,Lists!B:B,Lists!A:A,"") -> 5 | D10: A&B | E10: 1 | F10: 160 | G10: =IF(OR(E10="",F10=""),"",F10-E10+1) -> 160 | H10: =IF(D10="","",IF(OR(D10="A",D10="B"),G10/80,IF(D10="A&B",G10/160,""))) -> 1 | I10: Trolls 25% EW | J10: =IF(I10="","",_xlfn.XLOOKUP(I10,Lists!$C:$C,Lists!$D:$D)) -> Tebuconazole 25% | K10: Spray | L10: 100 | M10: 900 | N10: =IF(OR(M10="",L10=""),"",(M10*L10)/100000) -> 0.9 | O10: =IF(I10="","",_xlfn.XLOOKUP(I10,Lists!$C:$C,Lists!$J:$J)) -> L | P10: =IF(I10="","",_xlfn.XLOOKUP(I10,Lists!$C:$C,Lists!$E:$E)) -> 45 | Q10: =IF(OR(A10="",P10=""),"",A10+P10+1) -> 46195 | R10: =IF(Q10="","",IF(Q10<=TODAY(),"Allow","Not Allow")) -> Not Allow | S10: =IF(I10="","",_xlfn.XLOOKUP(I10,Lists!$C:$C,Lists!$I:$I)) -> On-Label
A11: 46150 | B11: 10 | C11: =_xlfn.XLOOKUP(B11,Lists!B:B,Lists!A:A,"") -> 1 | D11: A&B | E11: 1 | F11: 160 | G11: =IF(OR(E11="",F11=""),"",F11-E11+1) -> 160 | H11: =IF(D11="","",IF(OR(D11="A",D11="B"),G11/80,IF(D11="A&B",G11/160,""))) -> 1 | I11: Trolls 25% EW | J11: =IF(I11="","",_xlfn.XLOOKUP(I11,Lists!$C:$C,Lists!$D:$D)) -> Tebuconazole 25% | K11: Spray | L11: 100 | M11: 900 | N11: =IF(OR(M11="",L11=""),"",(M11*L11)/100000) -> 0.9 | O11: =IF(I11="","",_xlfn.XLOOKUP(I11,Lists!$C:$C,Lists!$J:$J)) -> L | P11: =IF(I11="","",_xlfn.XLOOKUP(I11,Lists!$C:$C,Lists!$E:$E)) -> 45 | Q11: =IF(OR(A11="",P11=""),"",A11+P11+1) -> 46196 | R11: =IF(Q11="","",IF(Q11<=TODAY(),"Allow","Not Allow")) -> Not Allow | S11: =IF(I11="","",_xlfn.XLOOKUP(I11,Lists!$C:$C,Lists!$I:$I)) -> On-Label
A12: 46150 | B12: 23 | C12: =_xlfn.XLOOKUP(B12,Lists!B:B,Lists!A:A,"") -> 3 | D12: A&B | E12: 1 | F12: 160 | G12: =IF(OR(E12="",F12=""),"",F12-E12+1) -> 160 | H12: =IF(D12="","",IF(OR(D12="A",D12="B"),G12/80,IF(D12="A&B",G12/160,""))) -> 1 | I12: Trolls 25% EW | J12: =IF(I12="","",_xlfn.XLOOKUP(I12,Lists!$C:$C,Lists!$D:$D)) -> Tebuconazole 25% | K12: Spray | L12: 100 | M12: 900 | N12: =IF(OR(M12="",L12=""),"",(M12*L12)/100000) -> 0.9 | O12: =IF(I12="","",_xlfn.XLOOKUP(I12,Lists!$C:$C,Lists!$J:$J)) -> L | P12: =IF(I12="","",_xlfn.XLOOKUP(I12,Lists!$C:$C,Lists!$E:$E)) -> 45 | Q12: =IF(OR(A12="",P12=""),"",A12+P12+1) -> 46196 | R12: =IF(Q12="","",IF(Q12<=TODAY(),"Allow","Not Allow")) -> Not Allow | S12: =IF(I12="","",_xlfn.XLOOKUP(I12,Lists!$C:$C,Lists!$I:$I)) -> On-Label
A13: 46150 | B13: 46 | C13: =_xlfn.XLOOKUP(B13,Lists!B:B,Lists!A:A,"") -> 4 | D13: A&B | E13: 1 | F13: 160 | G13: =IF(OR(E13="",F13=""),"",F13-E13+1) -> 160 | H13: =IF(D13="","",IF(OR(D13="A",D13="B"),G13/80,IF(D13="A&B",G13/160,""))) -> 1 | I13: Trolls 25% EW | J13: =IF(I13="","",_xlfn.XLOOKUP(I13,Lists!$C:$C,Lists!$D:$D)) -> Tebuconazole 25% | K13: Spray | L13: 100 | M13: 900 | N13: =IF(OR(M13="",L13=""),"",(M13*L13)/100000) -> 0.9 | O13: =IF(I13="","",_xlfn.XLOOKUP(I13,Lists!$C:$C,Lists!$J:$J)) -> L | P13: =IF(I13="","",_xlfn.XLOOKUP(I13,Lists!$C:$C,Lists!$E:$E)) -> 45 | Q13: =IF(OR(A13="",P13=""),"",A13+P13+1) -> 46196 | R13: =IF(Q13="","",IF(Q13<=TODAY(),"Allow","Not Allow")) -> Not Allow | S13: =IF(I13="","",_xlfn.XLOOKUP(I13,Lists!$C:$C,Lists!$I:$I)) -> On-Label
... A55: 46165 | B55: 5 | C55: =_xlfn.XLOOKUP(B55,Lists!B:B,Lists!A:A,"") -> 1 | D55: A&B | E55: 1 | F55: 160 | G55: =IF(OR(E55="",F55=""),"",F55-E55+1) -> 160 | H55: =IF(D55="","",IF(OR(D55="A",D55="B"),G55/80,IF(D55="A&B",G55/160,""))) -> 1 | I55: Mosiplan 20% SP | J55: =IF(I55="","",_xlfn.XLOOKUP(I55,Lists!$C:$C,Lists!$D:$D)) -> Acetamiprid [20%] | K55: Injection | L55: 7500 | M55: 20 | N55: =IF(OR(M55="",L55=""),"",(M55*L55)/100000) -> 1.5 | O55: =IF(I55="","",_xlfn.XLOOKUP(I55,Lists!$C:$C,Lists!$J:$J)) -> Kg | P55: =IF(I55="","",_xlfn.XLOOKUP(I55,Lists!$C:$C,Lists!$E:$E)) -> 5 | Q55: =IF(OR(A55="",P55=""),"",A55+P55+1) -> 46171 | R55: =IF(Q55="","",IF(Q55<=TODAY(),"Allow","Not Allow")) -> Allow | S55: =IF(I55="","",_xlfn.XLOOKUP(I55,Lists!$C:$C,Lists!$I:$I)) -> On-Label
A56: 46165 | B56: 4 | C56: =_xlfn.XLOOKUP(B56,Lists!B:B,Lists!A:A,"") -> 1 | D56: A&B | E56: 1 | F56: 160 | G56: =IF(OR(E56="",F56=""),"",F56-E56+1) -> 160 | H56: =IF(D56="","",IF(OR(D56="A",D56="B"),G56/80,IF(D56="A&B",G56/160,""))) -> 1 | I56: Mosiplan 20% SP | J56: =IF(I56="","",_xlfn.XLOOKUP(I56,Lists!$C:$C,Lists!$D:$D)) -> Acetamiprid [20%] | K56: Injection | L56: 7500 | M56: 20 | N56: =IF(OR(M56="",L56=""),"",(M56*L56)/100000) -> 1.5 | O56: =IF(I56="","",_xlfn.XLOOKUP(I56,Lists!$C:$C,Lists!$J:$J)) -> Kg | P56: =IF(I56="","",_xlfn.XLOOKUP(I56,Lists!$C:$C,Lists!$E:$E)) -> 5 | Q56: =IF(OR(A56="",P56=""),"",A56+P56+1) -> 46171 | R56: =IF(Q56="","",IF(Q56<=TODAY(),"Allow","Not Allow")) -> Allow | S56: =IF(I56="","",_xlfn.XLOOKUP(I56,Lists!$C:$C,Lists!$I:$I)) -> On-Label | X56: =1500*5 -> 7500
A57: 46166 | B57: 23 | C57: =_xlfn.XLOOKUP(B57,Lists!B:B,Lists!A:A,"") -> 3 | D57: A&B | E57: 1 | F57: 160 | G57: =IF(OR(E57="",F57=""),"",F57-E57+1) -> 160 | H57: =IF(D57="","",IF(OR(D57="A",D57="B"),G57/80,IF(D57="A&B",G57/160,""))) -> 1 | I57: Mosiplan 20% SP | J57: =IF(I57="","",_xlfn.XLOOKUP(I57,Lists!$C:$C,Lists!$D:$D)) -> Acetamiprid [20%] | K57: Injection | L57: 7500 | M57: 20 | N57: =IF(OR(M57="",L57=""),"",(M57*L57)/100000) -> 1.5 | O57: =IF(I57="","",_xlfn.XLOOKUP(I57,Lists!$C:$C,Lists!$J:$J)) -> Kg | P57: =IF(I57="","",_xlfn.XLOOKUP(I57,Lists!$C:$C,Lists!$E:$E)) -> 5 | Q57: =IF(OR(A57="",P57=""),"",A57+P57+1) -> 46172 | R57: =IF(Q57="","",IF(Q57<=TODAY(),"Allow","Not Allow")) -> Allow | S57: =IF(I57="","",_xlfn.XLOOKUP(I57,Lists!$C:$C,Lists!$I:$I)) -> On-Label
A58: 46166 | B58: 28 | C58: =_xlfn.XLOOKUP(B58,Lists!B:B,Lists!A:A,"") -> 3 | D58: A&B | E58: 1 | F58: 160 | G58: =IF(OR(E58="",F58=""),"",F58-E58+1) -> 160 | H58: =IF(D58="","",IF(OR(D58="A",D58="B"),G58/80,IF(D58="A&B",G58/160,""))) -> 1 | I58: Mosiplan 20% SP | J58: =IF(I58="","",_xlfn.XLOOKUP(I58,Lists!$C:$C,Lists!$D:$D)) -> Acetamiprid [20%] | K58: Injection | L58: 7500 | M58: 20 | N58: =IF(OR(M58="",L58=""),"",(M58*L58)/100000) -> 1.5 | O58: =IF(I58="","",_xlfn.XLOOKUP(I58,Lists!$C:$C,Lists!$J:$J)) -> Kg | P58: =IF(I58="","",_xlfn.XLOOKUP(I58,Lists!$C:$C,Lists!$E:$E)) -> 5 | Q58: =IF(OR(A58="",P58=""),"",A58+P58+1) -> 46172 | R58: =IF(Q58="","",IF(Q58<=TODAY(),"Allow","Not Allow")) -> Allow | S58: =IF(I58="","",_xlfn.XLOOKUP(I58,Lists!$C:$C,Lists!$I:$I)) -> On-Label
A59: 46167 | B59: 32 | C59: =_xlfn.XLOOKUP(B59,Lists!B:B,Lists!A:A,"") -> 5 | D59: A&B | E59: 1 | F59: 160 | G59: =IF(OR(E59="",F59=""),"",F59-E59+1) -> 160 | H59: =IF(D59="","",IF(OR(D59="A",D59="B"),G59/80,IF(D59="A&B",G59/160,""))) -> 1 | I59: Mosiplan 20% SP | J59: =IF(I59="","",_xlfn.XLOOKUP(I59,Lists!$C:$C,Lists!$D:$D)) -> Acetamiprid [20%] | K59: Injection | L59: 7500 | M59: 20 | N59: =IF(OR(M59="",L59=""),"",(M59*L59)/100000) -> 1.5 | O59: =IF(I59="","",_xlfn.XLOOKUP(I59,Lists!$C:$C,Lists!$J:$J)) -> Kg | P59: =IF(I59="","",_xlfn.XLOOKUP(I59,Lists!$C:$C,Lists!$E:$E)) -> 5 | Q59: =IF(OR(A59="",P59=""),"",A59+P59+1) -> 46173 | R59: =IF(Q59="","",IF(Q59<=TODAY(),"Allow","Not Allow")) -> Allow | S59: =IF(I59="","",_xlfn.XLOOKUP(I59,Lists!$C:$C,Lists!$I:$I)) -> On-Label
A60: 46167 | B60: 37 | C60: =_xlfn.XLOOKUP(B60,Lists!B:B,Lists!A:A,"") -> 5 | D60: A&B | E60: 1 | F60: 160 | G60: =IF(OR(E60="",F60=""),"",F60-E60+1) -> 160 | H60: =IF(D60="","",IF(OR(D60="A",D60="B"),G60/80,IF(D60="A&B",G60/160,""))) -> 1 | I60: Mosiplan 20% SP | J60: =IF(I60="","",_xlfn.XLOOKUP(I60,Lists!$C:$C,Lists!$D:$D)) -> Acetamiprid [20%] | K60: Injection | L60: 7500 | M60: 20 | N60: =IF(OR(M60="",L60=""),"",(M60*L60)/100000) -> 1.5 | O60: =IF(I60="","",_xlfn.XLOOKUP(I60,Lists!$C:$C,Lists!$J:$J)) -> Kg | P60: =IF(I60="","",_xlfn.XLOOKUP(I60,Lists!$C:$C,Lists!$E:$E)) -> 5 | Q60: =IF(OR(A60="",P60=""),"",A60+P60+1) -> 46173 | R60: =IF(Q60="","",IF(Q60<=TODAY(),"Allow","Not Allow")) -> Allow | S60: =IF(I60="","",_xlfn.XLOOKUP(I60,Lists!$C:$C,Lists!$I:$I)) -> On-Label
A61: 46167 | B61: 42 | C61: =_xlfn.XLOOKUP(B61,Lists!B:B,Lists!A:A,"") -> 5 | D61: A&B | E61: 1 | F61: 160 | G61: =IF(OR(E61="",F61=""),"",F61-E61+1) -> 160 | H61: =IF(D61="","",IF(OR(D61="A",D61="B"),G61/80,IF(D61="A&B",G61/160,""))) -> 1 | I61: Mosiplan 20% SP | J61: =IF(I61="","",_xlfn.XLOOKUP(I61,Lists!$C:$C,Lists!$D:$D)) -> Acetamiprid [20%] | K61: Injection | L61: 7500 | M61: 20 | N61: =IF(OR(M61="",L61=""),"",(M61*L61)/100000) -> 1.5 | O61: =IF(I61="","",_xlfn.XLOOKUP(I61,Lists!$C:$C,Lists!$J:$J)) -> Kg | P61: =IF(I61="","",_xlfn.XLOOKUP(I61,Lists!$C:$C,Lists!$E:$E)) -> 5 | Q61: =IF(OR(A61="",P61=""),"",A61+P61+1) -> 46173 | R61: =IF(Q61="","",IF(Q61<=TODAY(),"Allow","Not Allow")) -> Allow | S61: =IF(I61="","",_xlfn.XLOOKUP(I61,Lists!$C:$C,Lists!$I:$I)) -> On-Label
A62: 46167 | B62: 4 | C62: =_xlfn.XLOOKUP(B62,Lists!B:B,Lists!A:A,"") -> 1 | D62: A&B | E62: 1 | F62: 160 | G62: =IF(OR(E62="",F62=""),"",F62-E62+1) -> 160 | H62: =IF(D62="","",IF(OR(D62="A",D62="B"),G62/80,IF(D62="A&B",G62/160,""))) -> 1 | I62: Delta Star 10% EC | J62: =IF(I62="","",_xlfn.XLOOKUP(I62,Lists!$C:$C,Lists!$D:$D)) -> Deltamethrin | K62: Spray | L62: 100 | M62: 900 | N62: =IF(OR(M62="",L62=""),"",(M62*L62)/100000) -> 0.9 | O62: =IF(I62="","",_xlfn.XLOOKUP(I62,Lists!$C:$C,Lists!$J:$J)) -> L | P62: =IF(I62="","",_xlfn.XLOOKUP(I62,Lists!$C:$C,Lists!$E:$E)) -> 10 | Q62: =IF(OR(A62="",P62=""),"",A62+P62+1) -> 46178 | R62: =IF(Q62="","",IF(Q62<=TODAY(),"Allow","Not Allow")) -> Allow | S62: =IF(I62="","",_xlfn.XLOOKUP(I62,Lists!$C:$C,Lists!$I:$I)) -> Off-Label
A63: 46167 | B63: 5 | C63: =_xlfn.XLOOKUP(B63,Lists!B:B,Lists!A:A,"") -> 1 | D63: A&B | E63: 1 | F63: 160 | G63: =IF(OR(E63="",F63=""),"",F63-E63+1) -> 160 | H63: =IF(D63="","",IF(OR(D63="A",D63="B"),G63/80,IF(D63="A&B",G63/160,""))) -> 1 | I63: Delta Star 10% EC | J63: =IF(I63="","",_xlfn.XLOOKUP(I63,Lists!$C:$C,Lists!$D:$D)) -> Deltamethrin | K63: Spray | L63: 100 | M63: 900 | N63: =IF(OR(M63="",L63=""),"",(M63*L63)/100000) -> 0.9 | O63: =IF(I63="","",_xlfn.XLOOKUP(I63,Lists!$C:$C,Lists!$J:$J)) -> L | P63: =IF(I63="","",_xlfn.XLOOKUP(I63,Lists!$C:$C,Lists!$E:$E)) -> 10 | Q63: =IF(OR(A63="",P63=""),"",A63+P63+1) -> 46178 | R63: =IF(Q63="","",IF(Q63<=TODAY(),"Allow","Not Allow")) -> Allow | S63: =IF(I63="","",_xlfn.XLOOKUP(I63,Lists!$C:$C,Lists!$I:$I)) -> Off-Label
A64: 46167 | B64: 10 | C64: =_xlfn.XLOOKUP(B64,Lists!B:B,Lists!A:A,"") -> 1 | D64: A&B | E64: 1 | F64: 160 | G64: =IF(OR(E64="",F64=""),"",F64-E64+1) -> 160 | H64: =IF(D64="","",IF(OR(D64="A",D64="B"),G64/80,IF(D64="A&B",G64/160,""))) -> 1 | I64: Delta Star 10% EC | J64: =IF(I64="","",_xlfn.XLOOKUP(I64,Lists!$C:$C,Lists!$D:$D)) -> Deltamethrin | K64: Spray | L64: 100 | M64: 900 | N64: =IF(OR(M64="",L64=""),"",(M64*L64)/100000) -> 0.9 | O64: =IF(I64="","",_xlfn.XLOOKUP(I64,Lists!$C:$C,Lists!$J:$J)) -> L | P64: =IF(I64="","",_xlfn.XLOOKUP(I64,Lists!$C:$C,Lists!$E:$E)) -> 10 | Q64: =IF(OR(A64="",P64=""),"",A64+P64+1) -> 46178 | R64: =IF(Q64="","",IF(Q64<=TODAY(),"Allow","Not Allow")) -> Allow | S64: =IF(I64="","",_xlfn.XLOOKUP(I64,Lists!$C:$C,Lists!$I:$I)) -> Off-Label
A65: 46167 | B65: 13 | C65: =_xlfn.XLOOKUP(B65,Lists!B:B,Lists!A:A,"") -> 2 | D65: A&B | E65: 1 | F65: 160 | G65: =IF(OR(E65="",F65=""),"",F65-E65+1) -> 160 | H65: =IF(D65="","",IF(OR(D65="A",D65="B"),G65/80,IF(D65="A&B",G65/160,""))) -> 1 | I65: Delta Star 10% EC | J65: =IF(I65="","",_xlfn.XLOOKUP(I65,Lists!$C:$C,Lists!$D:$D)) -> Deltamethrin | K65: Spray | L65: 100 | M65: 900 | N65: =IF(OR(M65="",L65=""),"",(M65*L65)/100000) -> 0.9 | O65: =IF(I65="","",_xlfn.XLOOKUP(I65,Lists!$C:$C,Lists!$J:$J)) -> L | P65: =IF(I65="","",_xlfn.XLOOKUP(I65,Lists!$C:$C,Lists!$E:$E)) -> 10 | Q65: =IF(OR(A65="",P65=""),"",A65+P65+1) -> 46178 | R65: =IF(Q65="","",IF(Q65<=TODAY(),"Allow","Not Allow")) -> Allow | S65: =IF(I65="","",_xlfn.XLOOKUP(I65,Lists!$C:$C,Lists!$I:$I)) -> Off-Label
A66: 46168 | B66: 46 | C66: =_xlfn.XLOOKUP(B66,Lists!B:B,Lists!A:A,"") -> 4 | D66: A&B | E66: 1 | F66: 160 | G66: =IF(OR(E66="",F66=""),"",F66-E66+1) -> 160 | H66: =IF(D66="","",IF(OR(D66="A",D66="B"),G66/80,IF(D66="A&B",G66/160,""))) -> 1 | I66: Mosiplan 20% SP | J66: =IF(I66="","",_xlfn.XLOOKUP(I66,Lists!$C:$C,Lists!$D:$D)) -> Acetamiprid [20%] | K66: Injection | L66: 7500 | M66: 20 | N66: =IF(OR(M66="",L66=""),"",(M66*L66)/100000) -> 1.5 | O66: =IF(I66="","",_xlfn.XLOOKUP(I66,Lists!$C:$C,Lists!$J:$J)) -> Kg | P66: =IF(I66="","",_xlfn.XLOOKUP(I66,Lists!$C:$C,Lists!$E:$E)) -> 5 | Q66: =IF(OR(A66="",P66=""),"",A66+P66+1) -> 46174 | R66: =IF(Q66="","",IF(Q66<=TODAY(),"Allow","Not Allow")) -> Allow | S66: =IF(I66="","",_xlfn.XLOOKUP(I66,Lists!$C:$C,Lists!$I:$I)) -> On-Label
A67: 46168 | B67: 47 | C67: =_xlfn.XLOOKUP(B67,Lists!B:B,Lists!A:A,"") -> 4 | D67: A&B | E67: 1 | F67: 160 | G67: =IF(OR(E67="",F67=""),"",F67-E67+1) -> 160 | H67: =IF(D67="","",IF(OR(D67="A",D67="B"),G67/80,IF(D67="A&B",G67/160,""))) -> 1 | I67: Mosiplan 20% SP | J67: =IF(I67="","",_xlfn.XLOOKUP(I67,Lists!$C:$C,Lists!$D:$D)) -> Acetamiprid [20%] | K67: Injection | L67: 7500 | M67: 20 | N67: =IF(OR(M67="",L67=""),"",(M67*L67)/100000) -> 1.5 | O67: =IF(I67="","",_xlfn.XLOOKUP(I67,Lists!$C:$C,Lists!$J:$J)) -> Kg | P67: =IF(I67="","",_xlfn.XLOOKUP(I67,Lists!$C:$C,Lists!$E:$E)) -> 5 | Q67: =IF(OR(A67="",P67=""),"",A67+P67+1) -> 46174 | R67: =IF(Q67="","",IF(Q67<=TODAY(),"Allow","Not Allow")) -> Allow | S67: =IF(I67="","",_xlfn.XLOOKUP(I67,Lists!$C:$C,Lists!$I:$I)) -> On-Label
A68: 46168 | B68: 51 | C68: =_xlfn.XLOOKUP(B68,Lists!B:B,Lists!A:A,"") -> 4 | D68: A&B | E68: 1 | F68: 160 | G68: =IF(OR(E68="",F68=""),"",F68-E68+1) -> 160 | H68: =IF(D68="","",IF(OR(D68="A",D68="B"),G68/80,IF(D68="A&B",G68/160,""))) -> 1 | I68: Mosiplan 20% SP | J68: =IF(I68="","",_xlfn.XLOOKUP(I68,Lists!$C:$C,Lists!$D:$D)) -> Acetamiprid [20%] | K68: Injection | L68: 7500 | M68: 20 | N68: =IF(OR(M68="",L68=""),"",(M68*L68)/100000) -> 1.5 | O68: =IF(I68="","",_xlfn.XLOOKUP(I68,Lists!$C:$C,Lists!$J:$J)) -> Kg | P68: =IF(I68="","",_xlfn.XLOOKUP(I68,Lists!$C:$C,Lists!$E:$E)) -> 5 | Q68: =IF(OR(A68="",P68=""),"",A68+P68+1) -> 46174 | R68: =IF(Q68="","",IF(Q68<=TODAY(),"Allow","Not Allow")) -> Allow | S68: =IF(I68="","",_xlfn.XLOOKUP(I68,Lists!$C:$C,Lists!$I:$I)) -> On-Label
... A90: 46173 | B90: 58 | C90: =_xlfn.XLOOKUP(B90,Lists!B:B,Lists!A:A,"") -> 4 | D90: A&B | E90: 1 | F90: 160 | G90: =IF(OR(E90="",F90=""),"",F90-E90+1) -> 160 | H90: =IF(D90="","",IF(OR(D90="A",D90="B"),G90/80,IF(D90="A&B",G90/160,""))) -> 1 | I90: Delta Star 10% EC | J90: =IF(I90="","",_xlfn.XLOOKUP(I90,Lists!$C:$C,Lists!$D:$D)) -> Deltamethrin | K90: Spray | L90: 100 | M90: 900 | N90: =IF(OR(M90="",L90=""),"",(M90*L90)/100000) -> 0.9 | O90: =IF(I90="","",_xlfn.XLOOKUP(I90,Lists!$C:$C,Lists!$J:$J)) -> L | P90: =IF(I90="","",_xlfn.XLOOKUP(I90,Lists!$C:$C,Lists!$E:$E)) -> 10 | Q90: =IF(OR(A90="",P90=""),"",A90+P90+1) -> 46184 | R90: =IF(Q90="","",IF(Q90<=TODAY(),"Allow","Not Allow")) -> Allow | S90: =IF(I90="","",_xlfn.XLOOKUP(I90,Lists!$C:$C,Lists!$I:$I)) -> Off-Label
C91: =_xlfn.XLOOKUP(B91,Lists!B:B,Lists!A:A,"") -> 0 | G91: =IF(OR(E91="",F91=""),"",F91-E91+1) | H91: =IF(D91="","",IF(OR(D91="A",D91="B"),G91/80,IF(D91="A&B",G91/160,""))) | J91: =IF(I91="","",_xlfn.XLOOKUP(I91,Lists!$C:$C,Lists!$D:$D)) | N91: =IF(OR(M91="",L91=""),"",(M91*L91)/100000) | O91: =IF(I91="","",_xlfn.XLOOKUP(I91,Lists!$C:$C,Lists!$J:$J)) | P91: =IF(I91="","",_xlfn.XLOOKUP(I91,Lists!$C:$C,Lists!$E:$E)) | Q91: =IF(OR(A91="",P91=""),"",A91+P91+1) | R91: =IF(Q91="","",IF(Q91<=TODAY(),"Allow","Not Allow")) | S91: =IF(I91="","",_xlfn.XLOOKUP(I91,Lists!$C:$C,Lists!$I:$I))
C92: =_xlfn.XLOOKUP(B92,Lists!B:B,Lists!A:A,"") -> 0 | G92: =IF(OR(E92="",F92=""),"",F92-E92+1) | H92: =IF(D92="","",IF(OR(D92="A",D92="B"),G92/80,IF(D92="A&B",G92/160,""))) | J92: =IF(I92="","",_xlfn.XLOOKUP(I92,Lists!$C:$C,Lists!$D:$D)) | N92: =IF(OR(M92="",L92=""),"",(M92*L92)/100000) | O92: =IF(I92="","",_xlfn.XLOOKUP(I92,Lists!$C:$C,Lists!$J:$J)) | P92: =IF(I92="","",_xlfn.XLOOKUP(I92,Lists!$C:$C,Lists!$E:$E)) | Q92: =IF(OR(A92="",P92=""),"",A92+P92+1) | R92: =IF(Q92="","",IF(Q92<=TODAY(),"Allow","Not Allow")) | S92: =IF(I92="","",_xlfn.XLOOKUP(I92,Lists!$C:$C,Lists!$I:$I))
C93: =_xlfn.XLOOKUP(B93,Lists!B:B,Lists!A:A,"") -> 0 | G93: =IF(OR(E93="",F93=""),"",F93-E93+1) | H93: =IF(D93="","",IF(OR(D93="A",D93="B"),G93/80,IF(D93="A&B",G93/160,""))) | J93: =IF(I93="","",_xlfn.XLOOKUP(I93,Lists!$C:$C,Lists!$D:$D)) | N93: =IF(OR(M93="",L93=""),"",(M93*L93)/100000) | O93: =IF(I93="","",_xlfn.XLOOKUP(I93,Lists!$C:$C,Lists!$J:$J)) | P93: =IF(I93="","",_xlfn.XLOOKUP(I93,Lists!$C:$C,Lists!$E:$E)) | Q93: =IF(OR(A93="",P93=""),"",A93+P93+1) | R93: =IF(Q93="","",IF(Q93<=TODAY(),"Allow","Not Allow")) | S93: =IF(I93="","",_xlfn.XLOOKUP(I93,Lists!$C:$C,Lists!$I:$I))
C94: =_xlfn.XLOOKUP(B94,Lists!B:B,Lists!A:A,"") -> 0 | G94: =IF(OR(E94="",F94=""),"",F94-E94+1) | H94: =IF(D94="","",IF(OR(D94="A",D94="B"),G94/80,IF(D94="A&B",G94/160,""))) | J94: =IF(I94="","",_xlfn.XLOOKUP(I94,Lists!$C:$C,Lists!$D:$D)) | N94: =IF(OR(M94="",L94=""),"",(M94*L94)/100000) | O94: =IF(I94="","",_xlfn.XLOOKUP(I94,Lists!$C:$C,Lists!$J:$J)) | P94: =IF(I94="","",_xlfn.XLOOKUP(I94,Lists!$C:$C,Lists!$E:$E)) | Q94: =IF(OR(A94="",P94=""),"",A94+P94+1) | R94: =IF(Q94="","",IF(Q94<=TODAY(),"Allow","Not Allow")) | S94: =IF(I94="","",_xlfn.XLOOKUP(I94,Lists!$C:$C,Lists!$I:$I))
C95: =_xlfn.XLOOKUP(B95,Lists!B:B,Lists!A:A,"") -> 0 | G95: =IF(OR(E95="",F95=""),"",F95-E95+1) | H95: =IF(D95="","",IF(OR(D95="A",D95="B"),G95/80,IF(D95="A&B",G95/160,""))) | J95: =IF(I95="","",_xlfn.XLOOKUP(I95,Lists!$C:$C,Lists!$D:$D)) | N95: =IF(OR(M95="",L95=""),"",(M95*L95)/100000) | O95: =IF(I95="","",_xlfn.XLOOKUP(I95,Lists!$C:$C,Lists!$J:$J)) | P95: =IF(I95="","",_xlfn.XLOOKUP(I95,Lists!$C:$C,Lists!$E:$E)) | Q95: =IF(OR(A95="",P95=""),"",A95+P95+1) | R95: =IF(Q95="","",IF(Q95<=TODAY(),"Allow","Not Allow")) | S95: =IF(I95="","",_xlfn.XLOOKUP(I95,Lists!$C:$C,Lists!$I:$I))
C96: =_xlfn.XLOOKUP(B96,Lists!B:B,Lists!A:A,"") -> 0 | G96: =IF(OR(E96="",F96=""),"",F96-E96+1) | H96: =IF(D96="","",IF(OR(D96="A",D96="B"),G96/80,IF(D96="A&B",G96/160,""))) | J96: =IF(I96="","",_xlfn.XLOOKUP(I96,Lists!$C:$C,Lists!$D:$D)) | N96: =IF(OR(M96="",L96=""),"",(M96*L96)/100000) | O96: =IF(I96="","",_xlfn.XLOOKUP(I96,Lists!$C:$C,Lists!$J:$J)) | P96: =IF(I96="","",_xlfn.XLOOKUP(I96,Lists!$C:$C,Lists!$E:$E)) | Q96: =IF(OR(A96="",P96=""),"",A96+P96+1) | R96: =IF(Q96="","",IF(Q96<=TODAY(),"Allow","Not Allow")) | S96: =IF(I96="","",_xlfn.XLOOKUP(I96,Lists!$C:$C,Lists!$I:$I))
C97: =_xlfn.XLOOKUP(B97,Lists!B:B,Lists!A:A,"") -> 0 | G97: =IF(OR(E97="",F97=""),"",F97-E97+1) | H97: =IF(D97="","",IF(OR(D97="A",D97="B"),G97/80,IF(D97="A&B",G97/160,""))) | J97: =IF(I97="","",_xlfn.XLOOKUP(I97,Lists!$C:$C,Lists!$D:$D)) | N97: =IF(OR(M97="",L97=""),"",(M97*L97)/100000) | O97: =IF(I97="","",_xlfn.XLOOKUP(I97,Lists!$C:$C,Lists!$J:$J)) | P97: =IF(I97="","",_xlfn.XLOOKUP(I97,Lists!$C:$C,Lists!$E:$E)) | Q97: =IF(OR(A97="",P97=""),"",A97+P97+1) | R97: =IF(Q97="","",IF(Q97<=TODAY(),"Allow","Not Allow")) | S97: =IF(I97="","",_xlfn.XLOOKUP(I97,Lists!$C:$C,Lists!$I:$I))
C98: =_xlfn.XLOOKUP(B98,Lists!B:B,Lists!A:A,"") -> 0 | G98: =IF(OR(E98="",F98=""),"",F98-E98+1) | H98: =IF(D98="","",IF(OR(D98="A",D98="B"),G98/80,IF(D98="A&B",G98/160,""))) | J98: =IF(I98="","",_xlfn.XLOOKUP(I98,Lists!$C:$C,Lists!$D:$D)) | N98: =IF(OR(M98="",L98=""),"",(M98*L98)/100000) | O98: =IF(I98="","",_xlfn.XLOOKUP(I98,Lists!$C:$C,Lists!$J:$J)) | P98: =IF(I98="","",_xlfn.XLOOKUP(I98,Lists!$C:$C,Lists!$E:$E)) | Q98: =IF(OR(A98="",P98=""),"",A98+P98+1) | R98: =IF(Q98="","",IF(Q98<=TODAY(),"Allow","Not Allow")) | S98: =IF(I98="","",_xlfn.XLOOKUP(I98,Lists!$C:$C,Lists!$I:$I))
C99: =_xlfn.XLOOKUP(B99,Lists!B:B,Lists!A:A,"") -> 0 | G99: =IF(OR(E99="",F99=""),"",F99-E99+1) | H99: =IF(D99="","",IF(OR(D99="A",D99="B"),G99/80,IF(D99="A&B",G99/160,""))) | J99: =IF(I99="","",_xlfn.XLOOKUP(I99,Lists!$C:$C,Lists!$D:$D)) | N99: =IF(OR(M99="",L99=""),"",(M99*L99)/100000) | O99: =IF(I99="","",_xlfn.XLOOKUP(I99,Lists!$C:$C,Lists!$J:$J)) | P99: =IF(I99="","",_xlfn.XLOOKUP(I99,Lists!$C:$C,Lists!$E:$E)) | Q99: =IF(OR(A99="",P99=""),"",A99+P99+1) | R99: =IF(Q99="","",IF(Q99<=TODAY(),"Allow","Not Allow")) | S99: =IF(I99="","",_xlfn.XLOOKUP(I99,Lists!$C:$C,Lists!$I:$I))
C100: =_xlfn.XLOOKUP(B100,Lists!B:B,Lists!A:A,"") -> 0 | G100: =IF(OR(E100="",F100=""),"",F100-E100+1) | H100: =IF(D100="","",IF(OR(D100="A",D100="B"),G100/80,IF(D100="A&B",G100/160,""))) | J100: =IF(I100="","",_xlfn.XLOOKUP(I100,Lists!$C:$C,Lists!$D:$D)) | N100: =IF(OR(M100="",L100=""),"",(M100*L100)/100000) | O100: =IF(I100="","",_xlfn.XLOOKUP(I100,Lists!$C:$C,Lists!$J:$J)) | P100: =IF(I100="","",_xlfn.XLOOKUP(I100,Lists!$C:$C,Lists!$E:$E)) | Q100: =IF(OR(A100="",P100=""),"",A100+P100+1) | R100: =IF(Q100="","",IF(Q100<=TODAY(),"Allow","Not Allow")) | S100: =IF(I100="","",_xlfn.XLOOKUP(I100,Lists!$C:$C,Lists!$I:$I))
C101: =_xlfn.XLOOKUP(B101,Lists!B:B,Lists!A:A,"") -> 0 | G101: =IF(OR(E101="",F101=""),"",F101-E101+1) | H101: =IF(D101="","",IF(OR(D101="A",D101="B"),G101/80,IF(D101="A&B",G101/160,""))) | J101: =IF(I101="","",_xlfn.XLOOKUP(I101,Lists!$C:$C,Lists!$D:$D)) | N101: =IF(OR(M101="",L101=""),"",(M101*L101)/100000) | O101: =IF(I101="","",_xlfn.XLOOKUP(I101,Lists!$C:$C,Lists!$J:$J)) | P101: =IF(I101="","",_xlfn.XLOOKUP(I101,Lists!$C:$C,Lists!$E:$E)) | Q101: =IF(OR(A101="",P101=""),"",A101+P101+1) | R101: =IF(Q101="","",IF(Q101<=TODAY(),"Allow","Not Allow")) | S101: =IF(I101="","",_xlfn.XLOOKUP(I101,Lists!$C:$C,Lists!$I:$I))
C102: =_xlfn.XLOOKUP(B102,Lists!B:B,Lists!A:A,"") -> 0 | G102: =IF(OR(E102="",F102=""),"",F102-E102+1) | H102: =IF(D102="","",IF(OR(D102="A",D102="B"),G102/80,IF(D102="A&B",G102/160,""))) | J102: =IF(I102="","",_xlfn.XLOOKUP(I102,Lists!$C:$C,Lists!$D:$D)) | N102: =IF(OR(M102="",L102=""),"",(M102*L102)/100000) | O102: =IF(I102="","",_xlfn.XLOOKUP(I102,Lists!$C:$C,Lists!$J:$J)) | P102: =IF(I102="","",_xlfn.XLOOKUP(I102,Lists!$C:$C,Lists!$E:$E)) | Q102: =IF(OR(A102="",P102=""),"",A102+P102+1) | R102: =IF(Q102="","",IF(Q102<=TODAY(),"Allow","Not Allow")) | S102: =IF(I102="","",_xlfn.XLOOKUP(I102,Lists!$C:$C,Lists!$I:$I))
...
